
<?xml version="1.0" ?>
<!-- =================================================================================== -->
<!-- |    This document was autogenerated by xacro from /home/krr2rng/ros/tami_ws/src/tami_panda_resources/tami_panda_description/model/panda.xacro | -->
<!-- |    EDITING THIS FILE BY HAND IS NOT RECOMMENDED                                 | -->
<!-- =================================================================================== -->
<!-- this builds a complete panda arm with the panda gripper. Includes the necessary gazebo extensions -->
<robot name="panda">
  <!-- arbitrary value for mass -->
  <!-- MACRO DEFINITIONS -->
  <link name="panda_link0">
    <inertial>
      <origin rpy="0 0 0" xyz="-0.041018 -0.00014 0.049974"/>
      <inertia ixx="0.00315" iyy="0.00388" izz="0.004285" ixy="8.2904e-7" ixz="0.00015" iyz="8.2299e-6"/>
      <mass value="0.629769"/>
    </inertial>
  </link>
  <link name="panda_link1">
    <inertial>
      <origin rpy="0 0 0" xyz="0.003875 0.002081 -0.04762"/>
      <inertia ixx="0.70337" iyy="0.70661" izz="0.0091170" ixy="-0.00013900" ixz="0.0067720" iyz="0.019169"/>
      <mass value="4.970684"/>
    </inertial>
  </link>
  <link name="panda_link2">
       <inertial>
      <origin rpy="0 0 0" xyz="-0.003141 -0.02872 0.003495"/>
      <inertia ixx="0.0079620" iyy="2.8110e-2" izz="2.5995e-2" ixy="-3.925e-3" ixz="1.0254e-2" iyz="7.04e-4"/>
      <mass value="0.646926"/>
    </inertial>
  </link>
  <link name="panda_link3">
    <inertial>
      <origin rpy="0 0 0" xyz="2.7518e-2 3.9252e-2 -6.6502e-2"/>
      <inertia ixx="3.7242e-2" iyy="3.6155e-2" izz="1.083e-2" ixy="-4.761e-3" ixz="-1.1396e-2" iyz="-1.2805e-2"/>
      <mass value="3.228604"/>
    </inertial>
  </link>
  <link name="panda_link4">
    <inertial>
      <origin rpy="0 0 0" xyz="-5.317e-2 1.04419e-1 2.7454e-2"/>
      <inertia ixx="2.5853e-2" iyy="1.9552e-2" izz="2.8323e-2" ixy="7.796e-3" ixz="-1.332e-3" iyz="8.641e-3"/>
      <mass value="3.587895"/>
    </inertial>
  </link>
  <link name="panda_link5">
    <inertial>
      <origin rpy="0 0 0" xyz="-1.1953e-2 4.1065e-2 -3.8437e-2"/>
      <inertia ixx="3.5549e-2" iyy="2.9474e-2" izz="8.627e-3" ixy="-2.117e-3" ixz="-4.037e-3" iyz="2.29e-4"/>
      <mass value="1.225946"/>
    </inertial>
  </link>
  <link name="panda_link6">
    <inertial>
      <origin rpy="0 0 0" xyz="6.0149e-2 -1.4117e-2 -1.0517e-2"/>
      <inertia ixx="1.964e-3" iyy="4.354e-3" izz="5.433e-3" ixy="1.09e-4" ixz="-1.158e-3" iyz="3.41e-4"/>
      <mass value="1.666555"/>
    </inertial>
  </link>
  <link name="panda_link7">
    <inertial>
      <origin rpy="0 0 0" xyz="1.0517e-2 -4.252e-3 6.1597e-2"/>
      <inertia ixx="1.2516e-2" iyy="1.0027e-2" izz="4.815e-3" ixy="-4.28e-4" ixz="-1.196e-3" iyz="-7.41e-4"/>
      <mass value="7.35522e-01"/>
    </inertial>
  </link>
  <joint name="panda_joint1" type="revolute">
    <parent link="panda_link0"/>
    <child link="panda_link1"/>
    <safety_controller k_position="100.0" k_velocity="40.0" soft_lower_limit="-2.86" soft_upper_limit="2.86"/>
    <origin rpy="0 0 0" xyz="0 0 0.333"/>
    <axis xyz="0 0 1"/>
    <dynamics damping="0.0" friction="0.0"/>
    <limit effort="120" lower="-2.8973" upper="2.8973" velocity="2.3925"/>
  </joint>
  <joint name="panda_joint2" type="revolute">
    <parent link="panda_link1"/>
    <child link="panda_link2"/>
    <safety_controller k_position="100.0" k_velocity="40.0" soft_lower_limit="-1.72" soft_upper_limit="1.72"/>
    <origin rpy="-1.57079632679 0 0" xyz="0 0 0"/>
    <axis xyz="0 0 1"/>
    <dynamics damping="0.0" friction="0.0"/>
    <limit effort="120" lower="-1.7628" upper="1.7628" velocity="2.3925"/>
  </joint>
  <joint name="panda_joint3" type="revolute">
    <parent link="panda_link2"/>
    <child link="panda_link3"/>
    <safety_controller k_position="100.0" k_velocity="40.0" soft_lower_limit="-2.85" soft_upper_limit="2.88"/>
    <origin rpy="1.57079632679 0 0" xyz="0 -0.316 0"/>
    <axis xyz="0 0 1"/>
    <dynamics damping="0.0" friction="0.0"/>
    <limit effort="120" lower="-2.86" upper="2.8973" velocity="2.3925"/>
  </joint>
  <joint name="panda_joint4" type="revolute">
    <parent link="panda_link3"/>
    <child link="panda_link4"/>
    <safety_controller k_position="100.0" k_velocity="40.0" soft_lower_limit="-3.01" soft_upper_limit="-0.05"/>
    <origin rpy="1.57079632679 0 0" xyz="0.0825 0 0"/>
    <axis xyz="0 0 1"/>
    <dynamics damping="0.0" friction="0.0"/>
    <limit effort="120" lower="-3.03" upper="-0.0698" velocity="2.3925"/>
  </joint>
  <joint name="panda_joint5" type="revolute">
    <parent link="panda_link4"/>
    <child link="panda_link5"/>
    <safety_controller k_position="100.0" k_velocity="40.0" soft_lower_limit="-2.85" soft_upper_limit="2.85"/>
    <origin rpy="-1.57079632679 0 0" xyz="-0.0825 0.384 0"/>
    <axis xyz="0 0 1"/>
    <dynamics damping="0.0" friction="0.0"/>
    <limit effort="50" lower="-2.86" upper="2.86" velocity="2.8710"/>
  </joint>

  <joint name="panda_joint6" type="revolute">
    <parent link="panda_link5"/>
    <child link="panda_link6"/>
    <safety_controller k_position="100.0" k_velocity="40.0" soft_lower_limit="0.05" soft_upper_limit="3.7"/>
    <origin rpy="1.57079632679 0 0" xyz="0 0 0"/>
    <axis xyz="0 0 1"/>
    <dynamics damping="0.0" friction="0.0"/>
    <limit effort="50" lower="0.04" upper="3.71" velocity="2.8710"/>
  </joint>
  <joint name="panda_joint7" type="revolute">
    <parent link="panda_link6"/>
    <child link="panda_link7"/>
    <safety_controller k_position="100.0" k_velocity="40.0" soft_lower_limit="-2.8" soft_upper_limit="2.8"/>
    <origin rpy="1.57079632679 0 0" xyz="0.088 0 0"/>
    <axis xyz="0 0 1"/>
    <dynamics damping="0.0" friction="0.0"/>
    <limit effort="50" lower="-2.82" upper="2.82" velocity="2.8710"/>
  </joint>
  <link name="panda_link8"/>
  <joint name="panda_joint8" type="fixed">
    <origin rpy="0 0 -0.785398163397" xyz="0 0 0.107"/>
    <parent link="panda_link7"/>
    <child link="panda_link8"/>
    <axis xyz="0 0 0"/>
  </joint>
  <!-- uses the globally defined description_pkg property to find meshes etc. -->
  <joint name="hand_joint" type="fixed">
    <parent link="panda_link8"/>
    <child link="hand"/>
    <origin rpy="0 0 0" xyz="0 0 0"/>
  </joint>
  <!-- CONSTRUCT THE HAND -->
  <link name="hand">
    <inertial>
      <origin rpy="0 0 0" xyz="-0.01 0 0.03"/>
      <mass value="0.73"/>
      <inertia ixx="0.001" iyy="0.0025" izz="0.0017" ixy="0.0" ixz="0.0" iyz="0.0"/>
    </inertial>
  </link>
  <link name="left_finger">
    <inertial>
      <origin rpy="0 0 0" xyz="0.0 0.0 0.0"/>
      <mass value="0.015"/>
      <inertia ixx="2.375e-6" iyy="2.375e-6" izz="7.5e-7" ixy="0.0" ixz="0.0" iyz="0.0"/>
    </inertial>
  </link>
  <link name="right_finger">
    <inertial>
      <origin rpy="0 0 0" xyz="0 0 0"/>
      <mass value="0.015"/>
      <inertia ixx="2.375e-6" iyy="2.375e-6" izz="7.5e-7" ixy="0.0" ixz="0.0" iyz="0.0"/>
    </inertial>
  </link>
  <joint name="finger_joint1" type="prismatic">
    <parent link="hand"/>
    <child link="left_finger"/>
    <origin rpy="0 0 0" xyz="0 0 0.0584"/>
    <axis xyz="0 1 0"/>
    <!-- TODO: Not used in gripper plugin at the moment -->
    <limit effort="20" lower="0.0" upper="0.04" velocity="0.2"/>
    <!-- Gripper tag is used to identify joints of gripper -->
    <gripper/>
  </joint>
  <joint name="finger_joint2" type="prismatic">
    <parent link="hand"/>
    <child link="right_finger"/>
    <origin rpy="0 0 0" xyz="0 0 0.0584"/>
    <axis xyz="0 -1 0"/>
    <!-- TODO: Not used in gripper plugin at the moment -->
    <limit effort="20" lower="0.0" upper="0.04" velocity="0.2"/>
    <!-- Gripper tag is used to identify joints of gripper -->
    <gripper/>
  </joint>
  <!-- Define a Tool Center Point for this end effector -->
  <link name="panda_tool_center_point"/>
  <joint name="panda_tcp_joint" type="fixed">
    <origin rpy="0.0 0.0 0.0" xyz="0.0 0.0 0.1034"/>
    <parent link="hand"/>
    <child link="panda_tool_center_point"/>
    <axis xyz="0 0 0"/>
  </joint>

</robot>
